<robot name="onshape">
<link name="base_layer">
<visual>
<origin xyz="-0.0054085951405280288662 0.0063858766431100638661 -0.010733145442279119069" rpy="0 -0 0" />
<geometry>
<mesh filename="package://turtle_bot_description/turtle_bot/base_layer.stl"/>
</geometry>
<material name="base_layer_material">
<color rgba="0.14117647058823529216 0.43137254901960786491 0.7254901960784313486 1.0"/>
</material>
</visual>
<collision>
<origin xyz="-0.0054085951405280288662 0.0063858766431100638661 -0.010733145442279119069" rpy="0 -0 0" />
<geometry>
<mesh filename="package://turtle_bot_description/turtle_bot/base_layer.stl"/>
</geometry>
</collision>
<inertial>
<origin xyz="-0.005408595140528033203 0.0063858766431100647334 -0.013233145442279119555" rpy="0 0 0"/>
<mass value="0.076708445791032489613" />
<inertia ixx="0.00011517387353310793894" ixy="0"  ixz="0" iyy="8.9133149707990215016e-05" iyz="0" izz="0.00020398868575373323001" />
</inertial>
</link>

<link name="standoff">
<visual>
<origin xyz="0 0 0" rpy="3.141592653589793116 -0 0" />
<geometry>
<mesh filename="package://turtle_bot_description/turtle_bot/standoff.stl"/>
</geometry>
<material name="standoff_material">
<color rgba="0.91764705882352937127 0.91764705882352937127 0.91764705882352937127 1.0"/>
</material>
</visual>
<collision>
<origin xyz="0 0 0" rpy="3.141592653589793116 -0 0" />
<geometry>
<mesh filename="package://turtle_bot_description/turtle_bot/standoff.stl"/>
</geometry>
</collision>
<inertial>
<origin xyz="-1.2885779678748708114e-19 -9.2374474921235031905e-20 -0.053411456531411952153" rpy="0 0 0"/>
<mass value="0.0059281210142902648896" />
<inertia ixx="5.6380166401882050742e-06" ixy="0"  ixz="0" iyy="5.6380166401882050742e-06" iyz="0" izz="6.7280238291201044044e-09" />
</inertial>
</link>

<link name="mid_layer">
<visual>
<origin xyz="-0.030052038200428277809 0.030052038200428274339 -0.050000000000000002776" rpy="0 -0 0" />
<geometry>
<mesh filename="package://turtle_bot_description/turtle_bot/mid_layer.stl"/>
</geometry>
<material name="mid_layer_material">
<color rgba="0.14117647058823529216 0.43137254901960786491 0.7254901960784313486 1.0"/>
</material>
</visual>
<collision>
<origin xyz="-0.030052038200428277809 0.030052038200428274339 -0.050000000000000002776" rpy="0 -0 0" />
<geometry>
<mesh filename="package://turtle_bot_description/turtle_bot/mid_layer.stl"/>
</geometry>
</collision>
<inertial>
<origin xyz="-0.030052038200428277809 0.030052038200428277809 -0.0024999999999999952816" rpy="0 0 0"/>
<mass value="0.083011182331746063978" />
<inertia ixx="0.00011697427137894075811" ixy="0"  ixz="0" iyy="0.00011697427137894071745" iyz="0" izz="0.00023360266283149923186" />
</inertial>
</link>

<joint name="mid_joint_1" type="fixed">
<origin xyz="-3.4694469519536141888e-18 0 -0.052499999999999991118" rpy="3.141592653589793116 -0 0" />
<parent link="standoff" />
<child link="mid_layer" />
<axis xyz="0 0 1"/>
<limit effort="1" velocity="20" />
<joint_properties friction="0.0"/>
</joint>

<link name="top_layer">
<visual>
<origin xyz="-0.030052038200428277809 0.030052038200428274339 -0.10000000000000000555" rpy="0 -0 0" />
<geometry>
<mesh filename="package://turtle_bot_description/turtle_bot/top_layer.stl"/>
</geometry>
<material name="top_layer_material">
<color rgba="0.14117647058823529216 0.40784313725490195512 0.7254901960784313486 1.0"/>
</material>
</visual>
<collision>
<origin xyz="-0.030052038200428277809 0.030052038200428274339 -0.10000000000000000555" rpy="0 -0 0" />
<geometry>
<mesh filename="package://turtle_bot_description/turtle_bot/top_layer.stl"/>
</geometry>
</collision>
<inertial>
<origin xyz="-0.030052036065168211826 0.030052035531353181452 -0.0025000000000000022204" rpy="0 0 0"/>
<mass value="0.082705577310317260342" />
<inertia ixx="0.0001165988706191439816" ixy="-6.1809275542788895896e-12"  ixz="0" iyy="0.00011679231738675154018" iyz="0" izz="0.00023304658143376917774" />
</inertial>
</link>

<link name="lidar">
<visual>
<origin xyz="-0.027750000000000038525 -0.020000000000000007355 -0.024600000000000010747" rpy="-1.570796326794896558 -0 -1.7804189523299639519e-65" />
<geometry>
<mesh filename="package://turtle_bot_description/turtle_bot/lidar.stl"/>
</geometry>
<material name="lidar_material">
<color rgba="0.070588235294117646079 0.08627450980392156743 0.098039215686274508443 1.0"/>
</material>
</visual>
<collision>
<origin xyz="-0.027750000000000038525 -0.020000000000000007355 -0.024600000000000010747" rpy="-1.570796326794896558 -0 -1.7804189523299639519e-65" />
<geometry>
<mesh filename="package://turtle_bot_description/turtle_bot/lidar.stl"/>
</geometry>
</collision>
<inertial>
<origin xyz="-0.03523346988333641433 -0.019908073888912462823 -0.03526812773284024316" rpy="0 0 0"/>
<mass value="0.19842109046142825113" />
<inertia ixx="9.1685841634372709547e-05" ixy="1.1957791832927559532e-07"  ixz="-2.3594440914703952743e-05" iyy="0.00014324243606702940449" iyz="-4.6096994025815565616e-07" izz="0.00016373727901481947605" />
</inertial>
</link>

<joint name="lidar_base_1" type="fixed">
<origin xyz="-0.050052038200428278225 -0.0049479617995717289913 0" rpy="3.141592653589793116 -1.232595164407830946e-32 -1.570796326794896558" />
<parent link="top_layer" />
<child link="lidar" />
<axis xyz="0 0 1"/>
<limit effort="1" velocity="20" />
<joint_properties friction="0.0"/>
</joint>

<joint name="top_joint_1" type="fixed">
<origin xyz="-3.4694469519536141888e-18 0 -0.10499999999999999611" rpy="3.141592653589793116 -0 0" />
<parent link="standoff" />
<child link="top_layer" />
<axis xyz="0 0 1"/>
<limit effort="1" velocity="20" />
<joint_properties friction="0.0"/>
</joint>

<joint name="base_joint_1" type="fixed">
<origin xyz="0.024643443059900252412 -0.023666161557318210473 -0.015733145442279120041" rpy="3.141592653589793116 -0 0" />
<parent link="base_layer" />
<child link="standoff" />
<axis xyz="0 0 1"/>
<limit effort="1" velocity="20" />
<joint_properties friction="0.0"/>
</joint>

<link name="standoff_2">
<visual>
<origin xyz="0 0 0" rpy="3.141592653589793116 -0 0" />
<geometry>
<mesh filename="package://turtle_bot_description/turtle_bot/standoff.stl"/>
</geometry>
<material name="standoff_material">
<color rgba="0.91764705882352937127 0.91764705882352937127 0.91764705882352937127 1.0"/>
</material>
</visual>
<collision>
<origin xyz="0 0 0" rpy="3.141592653589793116 -0 0" />
<geometry>
<mesh filename="package://turtle_bot_description/turtle_bot/standoff.stl"/>
</geometry>
</collision>
<inertial>
<origin xyz="-1.2885779678748708114e-19 -9.2374474921235031905e-20 -0.053411456531411952153" rpy="0 0 0"/>
<mass value="0.0059281210142902648896" />
<inertia ixx="5.6380166401882050742e-06" ixy="0"  ixz="0" iyy="5.6380166401882050742e-06" iyz="0" izz="6.7280238291201044044e-09" />
</inertial>
</link>

<joint name="base_joint_2" type="fixed">
<origin xyz="-0.035460633340956310144 -0.023666161557318217412 -0.015733145442279120041" rpy="3.141592653589793116 -0 0" />
<parent link="base_layer" />
<child link="standoff_2" />
<axis xyz="0 0 1"/>
<limit effort="1" velocity="20" />
<joint_properties friction="0.0"/>
</joint>

<link name="standoff_3">
<visual>
<origin xyz="0 0 0" rpy="3.141592653589793116 -0 0" />
<geometry>
<mesh filename="package://turtle_bot_description/turtle_bot/standoff.stl"/>
</geometry>
<material name="standoff_material">
<color rgba="0.91764705882352937127 0.91764705882352937127 0.91764705882352937127 1.0"/>
</material>
</visual>
<collision>
<origin xyz="0 0 0" rpy="3.141592653589793116 -0 0" />
<geometry>
<mesh filename="package://turtle_bot_description/turtle_bot/standoff.stl"/>
</geometry>
</collision>
<inertial>
<origin xyz="-1.2885779678748708114e-19 -9.2374474921235031905e-20 -0.053411456531411952153" rpy="0 0 0"/>
<mass value="0.0059281210142902648896" />
<inertia ixx="5.6380166401882050742e-06" ixy="0"  ixz="0" iyy="5.6380166401882050742e-06" iyz="0" izz="6.7280238291201044044e-09" />
</inertial>
</link>

<joint name="base_joint_3" type="fixed">
<origin xyz="0.024643443059900252412 0.036437914843538331267 -0.015733145442279120041" rpy="3.141592653589793116 -0 0" />
<parent link="base_layer" />
<child link="standoff_3" />
<axis xyz="0 0 1"/>
<limit effort="1" velocity="20" />
<joint_properties friction="0.0"/>
</joint>

<link name="standoff_4">
<visual>
<origin xyz="0 0 0" rpy="3.141592653589793116 -0 0" />
<geometry>
<mesh filename="package://turtle_bot_description/turtle_bot/standoff.stl"/>
</geometry>
<material name="standoff_material">
<color rgba="0.91764705882352937127 0.91764705882352937127 0.91764705882352937127 1.0"/>
</material>
</visual>
<collision>
<origin xyz="0 0 0" rpy="3.141592653589793116 -0 0" />
<geometry>
<mesh filename="package://turtle_bot_description/turtle_bot/standoff.stl"/>
</geometry>
</collision>
<inertial>
<origin xyz="-1.2885779678748708114e-19 -9.2374474921235031905e-20 -0.053411456531411952153" rpy="0 0 0"/>
<mass value="0.0059281210142902648896" />
<inertia ixx="5.6380166401882050742e-06" ixy="0"  ixz="0" iyy="5.6380166401882050742e-06" iyz="0" izz="6.7280238291201044044e-09" />
</inertial>
</link>

<joint name="base_joint_4" type="fixed">
<origin xyz="-0.035460633340956282389 0.036437914843538338205 -0.015733145442279120041" rpy="3.141592653589793116 -0 0" />
<parent link="base_layer" />
<child link="standoff_4" />
<axis xyz="0 0 1"/>
<limit effort="1" velocity="20" />
<joint_properties friction="0.0"/>
</joint>

<link name="wheel">
<visual>
<origin xyz="1.7347234759768070944e-18 -1.7347234759768070944e-18 -0.0097931037703787721105" rpy="0 -0 -5.5511151231257839347e-17" />
<geometry>
<mesh filename="package://turtle_bot_description/turtle_bot/wheel.stl"/>
</geometry>
<material name="wheel_material">
<color rgba="0.62745098039215685404 0.6745098039215686736 0.67843137254901964006 1.0"/>
</material>
</visual>
<collision>
<origin xyz="1.7347234759768070944e-18 -1.7347234759768070944e-18 -0.0097931037703787721105" rpy="0 -0 -5.5511151231257839347e-17" />
<geometry>
<mesh filename="package://turtle_bot_description/turtle_bot/wheel.stl"/>
</geometry>
</collision>
<inertial>
<origin xyz="8.1697339154535336824e-19 -1.7354001317076551602e-18 -0.010000000000000007147" rpy="0 0 0"/>
<mass value="0.062953359098010322481" />
<inertia ixx="1.3557884731460577573e-05" ixy="-1.8807909613156600127e-37"  ixz="0" iyy="1.3557884731460572491e-05" iyz="0" izz="2.3145947892207558913e-05" />
</inertial>
</link>

<joint name="wheel_joint_1" type="continuous">
<origin xyz="0.080330040283809578394 0.0063858766431100629987 -0.013233145442279119555" rpy="-1.570796326794896558 1.2968984003411589967 -1.570796326794896558" />
<parent link="base_layer" />
<child link="wheel" />
<axis xyz="0 0 1"/>
<limit effort="1" velocity="20" />
<joint_properties friction="0.0"/>
</joint>

<link name="wheel_2">
<visual>
<origin xyz="0 0 -0.0097931037703787582327" rpy="0 -0 0" />
<geometry>
<mesh filename="package://turtle_bot_description/turtle_bot/wheel.stl"/>
</geometry>
<material name="wheel_material">
<color rgba="0.62745098039215685404 0.6745098039215686736 0.67843137254901964006 1.0"/>
</material>
</visual>
<collision>
<origin xyz="0 0 -0.0097931037703787582327" rpy="0 -0 0" />
<geometry>
<mesh filename="package://turtle_bot_description/turtle_bot/wheel.stl"/>
</geometry>
</collision>
<inertial>
<origin xyz="-9.1775008443145391876e-19 -6.7665573084812139498e-22 -0.0099999999999999932693" rpy="0 0 0"/>
<mass value="0.062953359098010322481" />
<inertia ixx="1.3557884731460580961e-05" ixy="0"  ixz="0" iyy="1.3557884731460579267e-05" iyz="0" izz="2.3145947892207558913e-05" />
</inertial>
</link>

<joint name="wheel_joint_2" type="continuous">
<origin xyz="-0.091147230564865622249 0.0063858766431100638661 -0.01323314544227911782" rpy="-0 -1.570796326794896558 0" />
<parent link="base_layer" />
<child link="wheel_2" />
<axis xyz="0 0 1"/>
<limit effort="1" velocity="20" />
<joint_properties friction="0.0"/>
</joint>


</robot>
